2024-05-25 07:02:30,642 [ERROR] [consumer.py:587 - on_unknown_task() ] celery.worker.consumer.consumer: Received unregistered task of type 'pd_ds.tasks.calculation'.
The message has been ignored and discarded.

Did you remember to import the module containing this task?
Or maybe you're using relative imports?

Please see
https://docs.celeryq.dev/en/latest/internals/protocol.html
for more information.

The full contents of the message body was:
'[[], {}, {"callbacks": null, "errbacks": null, "chain": null, "chord": null}]' (77b)

The full contents of the message headers:
{'lang': 'py', 'task': 'pd_ds.tasks.calculation', 'id': '8f136e35-91d1-4066-b43b-49fbeae746f2', 'shadow': None, 'eta': None, 'expires': None, 'group': None, 'group_index': None, 'retries': 0, 'timelimit': [None, None], 'root_id': '8f136e35-91d1-4066-b43b-49fbeae746f2', 'parent_id': None, 'argsrepr': '()', 'kwargsrepr': '{}', 'origin': 'gen84@8786886db5cf', 'ignore_result': False, 'replaced_task_nesting': 0, 'stamped_headers': None, 'stamps': {}}

The delivery info for this task is:
{'consumer_tag': 'None4', 'delivery_tag': 5, 'redelivered': False, 'exchange': '', 'routing_key': 'celery'}
Traceback (most recent call last):
  File "/usr/local/lib/python3.9/site-packages/celery/worker/consumer/consumer.py", line 658, in on_task_received
    strategy = strategies[type_]
KeyError: 'pd_ds.tasks.calculation'
2024-05-25 07:03:00,052 [ERROR] [consumer.py:587 - on_unknown_task() ] celery.worker.consumer.consumer: Received unregistered task of type 'pd_ds.celery.calculation'.
The message has been ignored and discarded.

Did you remember to import the module containing this task?
Or maybe you're using relative imports?

Please see
https://docs.celeryq.dev/en/latest/internals/protocol.html
for more information.

The full contents of the message body was:
'[[], {}, {"callbacks": null, "errbacks": null, "chain": null, "chord": null}]' (77b)

The full contents of the message headers:
{'lang': 'py', 'task': 'pd_ds.celery.calculation', 'id': 'c009c95d-276e-4e01-afa7-ecca34f57d12', 'shadow': None, 'eta': None, 'expires': None, 'group': None, 'group_index': None, 'retries': 0, 'timelimit': [None, None], 'root_id': 'c009c95d-276e-4e01-afa7-ecca34f57d12', 'parent_id': None, 'argsrepr': '()', 'kwargsrepr': '{}', 'origin': 'gen109@8786886db5cf', 'ignore_result': False, 'replaced_task_nesting': 0, 'stamped_headers': None, 'stamps': {}}

The delivery info for this task is:
{'consumer_tag': 'None4', 'delivery_tag': 6, 'redelivered': False, 'exchange': '', 'routing_key': 'celery'}
Traceback (most recent call last):
  File "/usr/local/lib/python3.9/site-packages/celery/worker/consumer/consumer.py", line 658, in on_task_received
    strategy = strategies[type_]
KeyError: 'pd_ds.celery.calculation'
2024-05-25 07:03:14,398 [INFO] [strategy.py:161 - task_message_handler() ] celery.worker.strategy: Task books.tasks.calculation[25f5a806-eca2-4eb3-892b-958d772602a4] received
2024-05-25 07:03:14,470 [INFO] [tasks.py:14 - calculation() ] books.tasks: jestem
2024-05-25 07:03:14,471 [INFO] [trace.py:131 - info() ] celery.app.trace: Task books.tasks.calculation[25f5a806-eca2-4eb3-892b-958d772602a4] succeeded in 0.07106359999988854s: None
2024-05-25 07:03:48,644 [INFO] [beat.py:632 - start() ] celery.beat: beat: Starting...
2024-05-25 07:04:00,014 [INFO] [beat.py:278 - apply_entry() ] celery.beat: Scheduler: Sending due task generate_reports_live (books.tasks.calculation)
2024-05-25 07:04:00,027 [INFO] [strategy.py:161 - task_message_handler() ] celery.worker.strategy: Task books.tasks.calculation[41314c66-c0e8-467d-83d0-55a5452d7965] received
2024-05-25 07:04:00,055 [INFO] [tasks.py:14 - calculation() ] books.tasks: jestem
